{"name": "test_vwo_login[chromium]", "status": "failed", "statusDetails": {"message": "AssertionError: Locator expected to have count '3'\nActual value: 5 \nCall log:\nLocatorAssertions.to_have_count with timeout 5000ms\nwaiting for get_by_role(\"listitem\")\n  locator resolved to 5 elements\n  unexpected value \"5\"\n  locator resolved to 5 elements\n  unexpected value \"5\"\n  locator resolved to 5 elements\n  unexpected value \"5\"\n  locator resolved to 5 elements\n  unexpected value \"5\"\n  locator resolved to 5 elements\n  unexpected value \"5\"\n  locator resolved to 5 elements\n  unexpected value \"5\"\n  locator resolved to 5 elements\n  unexpected value \"5\"\n  locator resolved to 5 elements\n  unexpected value \"5\"\n  locator resolved to 5 elements\n  unexpected value \"5\"", "trace": "page = <Page url='https://awesomeqa.com/pw/locators1.html'>\n\n    @allure.description(\"VWO Login\")\n    @pytest.mark.positive\n    def test_vwo_login(page: Page) -> None:\n        page.goto(\"https://awesomeqa.com/pw/locators1.html\")\n        page.wait_for_load_state(\"networkidle\")\n>       expect(page.get_by_role(\"listitem\")).to_have_count(3)\nE       AssertionError: Locator expected to have count '3'\nE       Actual value: 5 \nE       Call log:\nE       LocatorAssertions.to_have_count with timeout 5000ms\nE       waiting for get_by_role(\"listitem\")\nE         locator resolved to 5 elements\nE         unexpected value \"5\"\nE         locator resolved to 5 elements\nE         unexpected value \"5\"\nE         locator resolved to 5 elements\nE         unexpected value \"5\"\nE         locator resolved to 5 elements\nE         unexpected value \"5\"\nE         locator resolved to 5 elements\nE         unexpected value \"5\"\nE         locator resolved to 5 elements\nE         unexpected value \"5\"\nE         locator resolved to 5 elements\nE         unexpected value \"5\"\nE         locator resolved to 5 elements\nE         unexpected value \"5\"\nE         locator resolved to 5 elements\nE         unexpected value \"5\"\n\ntest_locators_003.py:12: AssertionError"}, "description": "VWO Login", "parameters": [{"name": "browser_name", "value": "'chromium'"}], "start": 1694427285544, "stop": 1694427296103, "uuid": "9e97e687-4aa0-4768-9ef3-e43fcc83f59c", "historyId": "ced16227a5ca05481ab06d2440f6240a", "testCaseId": "0f1381d5b7257282e920af1f4f679005", "fullName": "code.locators04.test_locators_003#test_vwo_login", "labels": [{"name": "tag", "value": "positive"}, {"name": "parentSuite", "value": "code.locators04"}, {"name": "suite", "value": "test_locators_003"}, {"name": "host", "value": "MBP-C02DRR20MD6M"}, {"name": "thread", "value": "7011-MainThread"}, {"name": "framework", "value": "pytest"}, {"name": "language", "value": "cpython3"}, {"name": "package", "value": "code.locators04.test_locators_003"}]}